Workbook
Name Slicer_Dept: #N/A
Name Slicer_Fiscal_Year: #N/A
Name Slicer_Quarter: #N/A

Sheet Dashboard
A1: Corporate Budget Variance Analysis - Fy 2024-2025

Sheet Insights
A1: Key Insights — Corporate Budget Variance Analysis
A3: 1. Departments consistently underspend against budget
A5: Business Question: Are departments spending in line with their approved budgets?
A6: Finding: Across all 6 departments and both fiscal years, actual spend was consistently lower than budgeted, ranging from -22% to -88% variance in realized quarters.
A7: Insight: This may indicate over-conservative budgeting, delayed spending execution, or gaps between the budgeting process and the general ledger's expense categories. Recommend a review with department heads to validate assumptions
A9: 2. Actual spend is stable regardless of budget fluctuation
A11: Business Question: Does actual spending track budget changes over time?
A12: Finding: While quarterly budgets varied significantly (from ~$330K to ~$580K company-wide), actual spend remained relatively flat (~$110K-$130K per quarter).
A13: Insight: This decoupling suggests the budgeting process may not be grounded in realistic operational spend patterns, or that departments have a fairly fixed cost
A14: structure regardless of approved budget.
A16: 3. Operations Q4 2024 shows the largest single variance
A18: Business Question: Which department/quarter combination represents the biggest planning gap?
... A27: Insight: Travel policy and vendor negotiation may offer the highest-leverage cost-control opportunity among expense categories.

Sheet Raw_Budget
A1: FiscalYear | B1: Dept | C1: Quarter | D1: BudgetUSD | E1: ForecastUSD | F1: ActualUSD | G1: VarianceUSD | H1: Notes | I1: Key
A2: 2024 | B2: Finance | C2: 1 | D2: 41215.19 | E2: 39758.93 | F2: 37613.91 | G2: -3601.28 | I2: =B2&A2&C2 -> Finance20241
A3: 2024 | B3: Finance | C3: 2 | D3: 79918.89 | E3: 84614.59 | F3: 86720.13 | G3: 6801.24 | I3: =B3&A3&C3 -> Finance20242
A4: 2024 | B4: Finance | C4: 3 | D4: 92014.18 | E4: 100763.08 | F4: 105980.31 | G4: 13966.13 | I4: =B4&A4&C4 -> Finance20243
A5: 2024 | B5: Finance | C5: 4 | D5: 117680.6 | E5: 106162.49 | F5: 96071.26 | G5: -21609.34 | I5: =B5&A5&C5 -> Finance20244
A6: 2024 | B6: HR | C6: 1 | D6: 32925.71 | E6: 30364.35 | F6: 30596.03 | G6: -2329.68 | I6: =B6&A6&C6 -> HR20241
A7: 2024 | B7: HR | C7: 2 | D7: 75074.82 | E7: 68249.88 | F7: 68953.81 | G7: -6121.01 | I7: =B7&A7&C7 -> HR20242
A8: 2024 | B8: HR | C8: 3 | D8: 42503.06 | E8: 44444.3 | F8: 42652.11 | G8: 149.05 | I8: =B8&A8&C8 -> HR20243
A9: 2024 | B9: HR | C9: 4 | D9: 31047.85 | E9: 32495.4 | F9: 33408.69 | G9: 2360.84 | I9: =B9&A9&C9 -> HR20244
A10: 2024 | B10: IT | C10: 1 | D10: 26040.63 | E10: 24585.53 | F10: 22752.02 | G10: -3288.61 | I10: =B10&A10&C10 -> IT20241
A11: 2024 | B11: IT | C11: 2 | D11: 125902.24 | E11: 121557.94 | F11: 119490.08 | G11: -6412.16 | I11: =B11&A11&C11 -> IT20242
A12: 2024 | B12: IT | C12: 3 | D12: 100055.73 | E12: 92809.65 | F12: 94502.07 | G12: -5553.66 | I12: =B12&A12&C12 -> IT20243
A13: 2024 | B13: IT | C13: 4 | D13: 72786.96 | E13: 70901.78 | F13: 72262.04 | G13: -524.92 | I13: =B13&A13&C13 -> IT20244
... A49: 2025 | B49: Operations | C49: 4 | D49: 28580.31 | E49: 29613.63 | F49: 28551.84 | G49: -28.47 | I49: =B49&A49&C49 -> Operations20254

Sheet Raw_GeneralLedger
A1: GLID | B1: TxnDate | C1: AccountNumber | D1: AccountName | E1: Debit | F1: Credit | G1: Dept | H1: CostCenter | I1: Description | J1: Currency | K1: Rate to USD | L1: Debit USD | M1: Credit USD | N1: Year | O1: Quarter
A2: GL000000 | B2: 45417 | C2: 4000 | D2: Sales Revenue | E2: 0 | F2: 2505.15 | G2: Sales | H2: CC500 | I2: AutoPost 0 | J2: GBP | K2: =VLOOKUP(J2,Exchange_Rates!A:B,2,FALSE) -> 1.27 | L2: =E2*K2 -> 0 | M2: =F2*K2 -> 3181.5405 | N2: =YEAR(B2) -> 2024 | O2: =ROUNDUP(MONTH(B2)/3,0) -> 2
A3: GL000001 | B3: 45466 | C3: 5000 | D3: COGS | E3: 1184.73 | F3: 0 | G3: HR | H3: CC500 | I3: AutoPost 1 | J3: GBP | K3: =VLOOKUP(J3,Exchange_Rates!A:B,2,FALSE) -> 1.27 | L3: =E3*K3 -> 1504.6071 | M3: =F3*K3 -> 0 | N3: =YEAR(B3) -> 2024 | O3: =ROUNDUP(MONTH(B3)/3,0) -> 2
A4: GL000002 | B4: 45666 | C4: 5000 | D4: COGS | E4: 748.25 | F4: 0 | G4: IT | H4: CC300 | I4: AutoPost 2 | J4: EUR | K4: =VLOOKUP(J4,Exchange_Rates!A:B,2,FALSE) -> 1.08 | L4: =E4*K4 -> 808.11 | M4: =F4*K4 -> 0 | N4: =YEAR(B4) -> 2025 | O4: =ROUNDUP(MONTH(B4)/3,0) -> 1
A5: GL000003 | B5: 45199 | C5: 6000 | D5: Payroll Expense | E5: 1610.64 | F5: 0 | G5: Sales | H5: CC400 | I5: AutoPost 3 | J5: AUD | K5: =VLOOKUP(J5,Exchange_Rates!A:B,2,FALSE) -> 0.66 | L5: =E5*K5 -> 1063.0224 | M5: =F5*K5 -> 0 | N5: =YEAR(B5) -> 2023 | O5: =ROUNDUP(MONTH(B5)/3,0) -> 3
A6: GL000004 | B6: 45141 | C6: 5000 | D6: COGS | E6: 1053.12 | F6: 0 | G6: HR | H6: CC400 | I6: AutoPost 4 | J6: USD | K6: =VLOOKUP(J6,Exchange_Rates!A:B,2,FALSE) -> 1 | L6: =E6*K6 -> 1053.12 | M6: =F6*K6 -> 0 | N6: =YEAR(B6) -> 2023 | O6: =ROUNDUP(MONTH(B6)/3,0) -> 3
A7: GL000005 | B7: 45788 | C7: 6000 | D7: Payroll Expense | E7: 1653.64 | F7: 0 | G7: Marketing | H7: CC400 | I7: AutoPost 5 | J7: USD | K7: =VLOOKUP(J7,Exchange_Rates!A:B,2,FALSE) -> 1 | L7: =E7*K7 -> 1653.64 | M7: =F7*K7 -> 0 | N7: =YEAR(B7) -> 2025 | O7: =ROUNDUP(MONTH(B7)/3,0) -> 2
A8: GL000006 | B8: 45142 | C8: 5010 | D8: Travel Expense | E8: 899.55 | F8: 0 | G8: HR | H8: CC200 | I8: AutoPost 6 | J8: USD | K8: =VLOOKUP(J8,Exchange_Rates!A:B,2,FALSE) -> 1 | L8: =E8*K8 -> 899.55 | M8: =F8*K8 -> 0 | N8: =YEAR(B8) -> 2023 | O8: =ROUNDUP(MONTH(B8)/3,0) -> 3
A9: GL000007 | B9: 45282 | C9: 6000 | D9: Payroll Expense | E9: 247.27 | F9: 0 | G9: Marketing | H9: CC500 | I9: AutoPost 7 | J9: USD | K9: =VLOOKUP(J9,Exchange_Rates!A:B,2,FALSE) -> 1 | L9: =E9*K9 -> 247.27 | M9: =F9*K9 -> 0 | N9: =YEAR(B9) -> 2023 | O9: =ROUNDUP(MONTH(B9)/3,0) -> 4
A10: GL000008 | B10: 45412 | C10: 5000 | D10: COGS | E10: 202.02 | F10: 0 | G10: Finance | H10: CC300 | I10: AutoPost 8 | J10: GBP | K10: =VLOOKUP(J10,Exchange_Rates!A:B,2,FALSE) -> 1.27 | L10: =E10*K10 -> 256.5654 | M10: =F10*K10 -> 0 | N10: =YEAR(B10) -> 2024 | O10: =ROUNDUP(MONTH(B10)/3,0) -> 2
A11: GL000009 | B11: 45029 | C11: 5000 | D11: COGS | E11: 1093.72 | F11: 0 | G11: HR | H11: CC400 | I11: AutoPost 9 | J11: USD | K11: =VLOOKUP(J11,Exchange_Rates!A:B,2,FALSE) -> 1 | L11: =E11*K11 -> 1093.72 | M11: =F11*K11 -> 0 | N11: =YEAR(B11) -> 2023 | O11: =ROUNDUP(MONTH(B11)/3,0) -> 2
A12: GL000010 | B12: 45250 | C12: 4010 | D12: Online Sales | E12: 0 | F12: 3282.35 | G12: Marketing | H12: CC100 | I12: AutoPost 10 | J12: CAD | K12: =VLOOKUP(J12,Exchange_Rates!A:B,2,FALSE) -> 0.73 | L12: =E12*K12 -> 0 | M12: =F12*K12 -> 2396.1155 | N12: =YEAR(B12) -> 2023 | O12: =ROUNDUP(MONTH(B12)/3,0) -> 4
A13: GL000011 | B13: 45608 | C13: 4000 | D13: Sales Revenue | E13: 0 | F13: 2452.2 | G13: Marketing | H13: CC200 | I13: AutoPost 11 | J13: EUR | K13: =VLOOKUP(J13,Exchange_Rates!A:B,2,FALSE) -> 1.08 | L13: =E13*K13 -> 0 | M13: =F13*K13 -> 2648.376 | N13: =YEAR(B13) -> 2024 | O13: =ROUNDUP(MONTH(B13)/3,0) -> 4
... A2001: GL001999 | B2001: 45555 | C2001: 4000 | D2001: Sales Revenue | E2001: 0 | F2001: 354.88 | G2001: HR | H2001: CC500 | I2001: AutoPost 1999 | J2001: USD | K2001: =VLOOKUP(J2001,Exchange_Rates!A:B,2,FALSE) -> 1 | L2001: =E2001*K2001 -> 0 | M2001: =F2001*K2001 -> 354.88 | N2001: =YEAR(B2001) -> 2024 | O2001: =ROUNDUP(MONTH(B2001)/3,0) -> 3

Sheet Raw_ExpenseClaims
A1: ClaimID | B1: EmployeeID | C1: SubmitDate | D1: Category | E1: Description | F1: Amount | G1: Currency | H1: Status | I1: ApprovedBy | J1: PayDate | K1: Rate to USD | L1: Amount USD
A2: CL30000 | B2: E1084 | C2: 45518 | D2: Supplies | E2: Travel expense | F2: 497.28 | G2: CAD | H2: Paid | I2: MgrC | J2: 45533 | K2: =VLOOKUP(G2,Exchange_Rates!A:B,2,FALSE) -> 0.73 | L2: =F2*K2 -> 363.0144
A3: CL30001 | B3: E1087 | C3: 45456 | D3: Supplies | E3: Travel expense | F3: 149.22 | G3: EUR | H3: Submitted | I3: MgrC | K3: =VLOOKUP(G3,Exchange_Rates!A:B,2,FALSE) -> 1.08 | L3: =F3*K3 -> 161.1576
A4: CL30002 | B4: E1083 | C4: 45186 | D4: Meals | E4: Travel expense | F4: 465.42 | G4: GBP | H4: Approved | I4: MgrC | K4: =VLOOKUP(G4,Exchange_Rates!A:B,2,FALSE) -> 1.27 | L4: =F4*K4 -> 591.0834
A5: CL30003 | B5: E1080 | C5: 45172 | D5: Travel | E5: Travel expense | F5: 262.72 | G5: CAD | H5: Paid | I5: MgrC | J5: 45187 | K5: =VLOOKUP(G5,Exchange_Rates!A:B,2,FALSE) -> 0.73 | L5: =F5*K5 -> 191.7856
A6: CL30004 | B6: E1040 | C6: 44935 | D6: Entertainment | E6: Travel expense | F6: 363.86 | G6: USD | H6: Submitted | I6: MgrB | K6: =VLOOKUP(G6,Exchange_Rates!A:B,2,FALSE) -> 1 | L6: =F6*K6 -> 363.86
A7: CL30005 | B7: E1039 | C7: 45501 | D7: Travel | E7: Travel expense | F7: 760.13 | G7: AUD | H7: Submitted | I7: MgrC | K7: =VLOOKUP(G7,Exchange_Rates!A:B,2,FALSE) -> 0.66 | L7: =F7*K7 -> 501.6858
A8: CL30006 | B8: E1006 | C8: 45248 | D8: Travel | E8: Travel expense | F8: 134.1 | G8: GBP | H8: Approved | I8: MgrB | K8: =VLOOKUP(G8,Exchange_Rates!A:B,2,FALSE) -> 1.27 | L8: =F8*K8 -> 170.307
A9: CL30007 | B9: E1109 | C9: 45055 | D9: Meals | E9: Travel expense | F9: 320.63 | G9: GBP | H9: Approved | I9: MgrB | K9: =VLOOKUP(G9,Exchange_Rates!A:B,2,FALSE) -> 1.27 | L9: =F9*K9 -> 407.2001
A10: CL30008 | B10: E1077 | C10: 45827 | D10: Supplies | E10: Travel expense | F10: 247.74 | G10: EUR | H10: Approved | I10: MgrC | K10: =VLOOKUP(G10,Exchange_Rates!A:B,2,FALSE) -> 1.08 | L10: =F10*K10 -> 267.5592
A11: CL30009 | B11: E1013 | C11: 45687 | D11: Supplies | E11: Travel expense | F11: 764.36 | G11: USD | H11: Approved | I11: MgrC | K11: =VLOOKUP(G11,Exchange_Rates!A:B,2,FALSE) -> 1 | L11: =F11*K11 -> 764.36
A12: CL30010 | B12: E1106 | C12: 45304 | D12: Travel | E12: Travel expense | F12: 762.2 | G12: GBP | H12: Paid | I12: MgrB | J12: 45319 | K12: =VLOOKUP(G12,Exchange_Rates!A:B,2,FALSE) -> 1.27 | L12: =F12*K12 -> 967.994
A13: CL30011 | B13: E1065 | C13: 45573 | D13: Supplies | E13: Travel expense | F13: 256.72 | G13: CAD | H13: Submitted | I13: MgrC | K13: =VLOOKUP(G13,Exchange_Rates!A:B,2,FALSE) -> 0.73 | L13: =F13*K13 -> 187.4056
A14: CL30012 | B14: E1021 | C14: 45606 | D14: Supplies | E14: Travel expense | F14: 338.15 | G14: GBP | H14: Submitted | I14: MgrA | K14: =VLOOKUP(G14,Exchange_Rates!A:B,2,FALSE) -> 1.27 | L14: =F14*K14 -> 429.4505
A15: CL30013 | B15: E1058 | C15: 45275 | D15: Travel | E15: Travel expense | F15: 144.3 | G15: CAD | H15: Submitted | I15: MgrB | K15: =VLOOKUP(G15,Exchange_Rates!A:B,2,FALSE) -> 0.73 | L15: =F15*K15 -> 105.339
A16: CL30014 | B16: E1068 | C16: 45441 | D16: Meals | E16: Travel expense | F16: 191.95 | G16: USD | H16: Paid | I16: MgrC | J16: 45456 | K16: =VLOOKUP(G16,Exchange_Rates!A:B,2,FALSE) -> 1 | L16: =F16*K16 -> 191.95
A17: CL30015 | B17: E1030 | C17: 45184 | D17: Entertainment | E17: Travel expense | F17: 742.94 | G17: USD | H17: Submitted | I17: MgrB | K17: =VLOOKUP(G17,Exchange_Rates!A:B,2,FALSE) -> 1 | L17: =F17*K17 -> 742.94
A18: CL30016 | B18: E1056 | C18: 45774 | D18: Training | E18: Travel expense | F18: 563.82 | G18: EUR | H18: Rejected | I18: MgrA | K18: =VLOOKUP(G18,Exchange_Rates!A:B,2,FALSE) -> 1.08 | L18: =F18*K18 -> 608.9256
A19: CL30017 | B19: E1091 | C19: 45267 | D19: Travel | E19: Travel expense | F19: 168.88 | G19: USD | H19: Approved | I19: MgrC | K19: =VLOOKUP(G19,Exchange_Rates!A:B,2,FALSE) -> 1 | L19: =F19*K19 -> 168.88
A20: CL30018 | B20: E1047 | C20: 45142 | D20: Travel | E20: Travel expense | F20: 763.43 | G20: EUR | H20: Rejected | I20: MgrA | K20: =VLOOKUP(G20,Exchange_Rates!A:B,2,FALSE) -> 1.08 | L20: =F20*K20 -> 824.5044
A21: CL30019 | B21: E1046 | C21: 45595 | D21: Training | E21: Travel expense | F21: 658.07 | G21: EUR | H21: Paid | I21: MgrB | J21: 45610 | K21: =VLOOKUP(G21,Exchange_Rates!A:B,2,FALSE) -> 1.08 | L21: =F21*K21 -> 710.7156
A22: CL30020 | B22: E1058 | C22: 45319 | D22: Training | E22: Travel expense | F22: 656.07 | G22: AUD | H22: Paid | I22: MgrB | J22: 45334 | K22: =VLOOKUP(G22,Exchange_Rates!A:B,2,FALSE) -> 0.66 | L22: =F22*K22 -> 433.0062
A23: CL30021 | B23: E1100 | C23: 44936 | D23: Training | E23: Travel expense | F23: 736.31 | G23: CAD | H23: Rejected | I23: MgrC | K23: =VLOOKUP(G23,Exchange_Rates!A:B,2,FALSE) -> 0.73 | L23: =F23*K23 -> 537.5063
A24: CL30022 | B24: E1037 | C24: 45383 | D24: Travel | E24: Travel expense | F24: 182.58 | G24: USD | H24: Rejected | I24: MgrA | K24: =VLOOKUP(G24,Exchange_Rates!A:B,2,FALSE) -> 1 | L24: =F24*K24 -> 182.58
A25: CL30023 | B25: E1039 | C25: 45062 | D25: Entertainment | E25: Travel expense | F25: 265.19 | G25: USD | H25: Submitted | I25: MgrC | K25: =VLOOKUP(G25,Exchange_Rates!A:B,2,FALSE) -> 1 | L25: =F25*K25 -> 265.19
A26: CL30024 | B26: E1040 | C26: 45313 | D26: Meals | E26: Travel expense | F26: 629.23 | G26: AUD | H26: Submitted | I26: MgrB | K26: =VLOOKUP(G26,Exchange_Rates!A:B,2,FALSE) -> 0.66 | L26: =F26*K26 -> 415.2918
A27: CL30025 | B27: E1103 | C27: 45618 | D27: Supplies | E27: Travel expense | F27: 408.85 | G27: GBP | H27: Paid | I27: MgrB | J27: 45633 | K27: =VLOOKUP(G27,Exchange_Rates!A:B,2,FALSE) -> 1.27 | L27: =F27*K27 -> 519.2395
A28: CL30026 | B28: E1056 | C28: 45185 | D28: Travel | E28: Travel expense | F28: 783.12 | G28: CAD | H28: Rejected | I28: MgrC | K28: =VLOOKUP(G28,Exchange_Rates!A:B,2,FALSE) -> 0.73 | L28: =F28*K28 -> 571.6776
A29: CL30027 | B29: E1067 | C29: 45709 | D29: Travel | E29: Travel expense | F29: 762.02 | G29: CAD | H29: Approved | I29: MgrB | K29: =VLOOKUP(G29,Exchange_Rates!A:B,2,FALSE) -> 0.73 | L29: =F29*K29 -> 556.2746
A30: CL30028 | B30: E1095 | C30: 45042 | D30: Supplies | E30: Travel expense | F30: 158.06 | G30: EUR | H30: Paid | I30: MgrC | J30: 45057 | K30: =VLOOKUP(G30,Exchange_Rates!A:B,2,FALSE) -> 1.08 | L30: =F30*K30 -> 170.7048
A31: CL30029 | B31: E1084 | C31: 45038 | D31: Supplies | E31: Travel expense | F31: 218.44 | G31: EUR | H31: Submitted | I31: MgrB | K31: =VLOOKUP(G31,Exchange_Rates!A:B,2,FALSE) -> 1.08 | L31: =F31*K31 -> 235.9152
A32: CL30030 | B32: E1041 | C32: 45225 | D32: Supplies | E32: Travel expense | F32: 682.85 | G32: USD | H32: Submitted | I32: MgrB | K32: =VLOOKUP(G32,Exchange_Rates!A:B,2,FALSE) -> 1 | L32: =F32*K32 -> 682.85
A33: CL30031 | B33: E1073 | C33: 45575 | D33: Entertainment | E33: Travel expense | F33: 118.8 | G33: AUD | H33: Approved | I33: MgrC | K33: =VLOOKUP(G33,Exchange_Rates!A:B,2,FALSE) -> 0.66 | L33: =F33*K33 -> 78.408
A34: CL30032 | B34: E1063 | C34: 45837 | D34: Entertainment | E34: Travel expense | F34: 101.52 | G34: USD | H34: Rejected | I34: MgrC | K34: =VLOOKUP(G34,Exchange_Rates!A:B,2,FALSE) -> 1 | L34: =F34*K34 -> 101.52
A35: CL30033 | B35: E1119 | C35: 45268 | D35: Meals | E35: Travel expense | F35: 201.77 | G35: AUD | H35: Paid | I35: MgrB | J35: 45283 | K35: =VLOOKUP(G35,Exchange_Rates!A:B,2,FALSE) -> 0.66 | L35: =F35*K35 -> 133.1682
A36: CL30034 | B36: E1106 | C36: 45185 | D36: Travel | E36: Travel expense | F36: 398.29 | G36: EUR | H36: Rejected | I36: MgrB | K36: =VLOOKUP(G36,Exchange_Rates!A:B,2,FALSE) -> 1.08 | L36: =F36*K36 -> 430.1532
A37: CL30035 | B37: E1050 | C37: 45085 | D37: Travel | E37: Travel expense | F37: 323.77 | G37: USD | H37: Paid | I37: MgrC | J37: 45100 | K37: =VLOOKUP(G37,Exchange_Rates!A:B,2,FALSE) -> 1 | L37: =F37*K37 -> 323.77
A38: CL30036 | B38: E1109 | C38: 45468 | D38: Training | E38: Travel expense | F38: 639.22 | G38: USD | H38: Submitted | I38: MgrC | K38: =VLOOKUP(G38,Exchange_Rates!A:B,2,FALSE) -> 1 | L38: =F38*K38 -> 639.22
A39: CL30037 | B39: E1005 | C39: 45013 | D39: Meals | E39: Travel expense | F39: 210.05 | G39: USD | H39: Approved | I39: MgrC | K39: =VLOOKUP(G39,Exchange_Rates!A:B,2,FALSE) -> 1 | L39: =F39*K39 -> 210.05
A40: CL30038 | B40: E1001 | C40: 45130 | D40: Travel | E40: Travel expense | F40: 359.73 | G40: EUR | H40: Submitted | I40: MgrB | K40: =VLOOKUP(G40,Exchange_Rates!A:B,2,FALSE) -> 1.08 | L40: =F40*K40 -> 388.5084
...

Sheet Data Quality Check
A1: Blank cells in Budget | B1: =COUNTBLANK([1]Raw_Bugedt!D2:D49) -> 0
A2: Duplicate GLIDs | B2: {=COUNTA(Raw_GeneralLedger!A2:A2001)-SUMPRODUCT(1/COUNTIF(Raw_GeneralLedger!A2:A2001,Raw_GeneralLedger!A2:A2001))} -> 0
A3: Dept names match (bud vs led) | B3: {=SUMPRODUCT(--(COUNTIF(Raw_GeneralLedger!G2:G2001, Raw_Budget!B2:B49)=0))} -> 0
A4: Max Debit USD | B4: =MAX(Raw_GeneralLedger!L2:L2001) -> 2531.5799
A5: Min Debit USD | B5: =MIN(Raw_GeneralLedger!L2:L2001) -> 0
A6: Average Debit USD | B6: =AVERAGE(Raw_GeneralLedger!L2:L2001) -> 564.7818

Sheet Exchange_Rates
A1: Currency | B1: Rate to USD
A2: USD | B2: 1
A3: EUR | B3: 1.08
A4: GBP | B4: 1.27
A5: CAD | B5: 0.73
A6: AUD | B6: 0.66

Sheet GL_Summary
A1: Fiscal Year | B1: Dept | C1: Quarter | D1: Actual Expense | E1: Actual Revenue | F1: Key
A2: 2024 | B2: Finance | C2: 1 | D2: =SUMIFS(Raw_GeneralLedger!L:L,Raw_GeneralLedger!G:G,B2,Raw_GeneralLedger!N:N,A2,Raw_GeneralLedger!O:O,C2) -> 20434.418 | E2: =SUMIFS(Raw_GeneralLedger!M:M,Raw_GeneralLedger!G:G,B2,Raw_GeneralLedger!N:N,A2,Raw_GeneralLedger!O:O,C2) -> 31519.725 | F2: =B2&A2&C2 -> Finance20241
A3: 2024 | B3: Finance | C3: 2 | D3: =SUMIFS(Raw_GeneralLedger!L:L,Raw_GeneralLedger!G:G,B3,Raw_GeneralLedger!N:N,A3,Raw_GeneralLedger!O:O,C3) -> 16330.416 | E3: =SUMIFS(Raw_GeneralLedger!M:M,Raw_GeneralLedger!G:G,B3,Raw_GeneralLedger!N:N,A3,Raw_GeneralLedger!O:O,C3) -> 35792.326 | F3: =B3&A3&C3 -> Finance20242
A4: 2024 | B4: Finance | C4: 3 | D4: =SUMIFS(Raw_GeneralLedger!L:L,Raw_GeneralLedger!G:G,B4,Raw_GeneralLedger!N:N,A4,Raw_GeneralLedger!O:O,C4) -> 19545.837 | E4: =SUMIFS(Raw_GeneralLedger!M:M,Raw_GeneralLedger!G:G,B4,Raw_GeneralLedger!N:N,A4,Raw_GeneralLedger!O:O,C4) -> 35806.628 | F4: =B4&A4&C4 -> Finance20243
A5: 2024 | B5: Finance | C5: 4 | D5: =SUMIFS(Raw_GeneralLedger!L:L,Raw_GeneralLedger!G:G,B5,Raw_GeneralLedger!N:N,A5,Raw_GeneralLedger!O:O,C5) -> 25935.929 | E5: =SUMIFS(Raw_GeneralLedger!M:M,Raw_GeneralLedger!G:G,B5,Raw_GeneralLedger!N:N,A5,Raw_GeneralLedger!O:O,C5) -> 35181.761 | F5: =B5&A5&C5 -> Finance20244
A6: 2024 | B6: HR | C6: 1 | D6: =SUMIFS(Raw_GeneralLedger!L:L,Raw_GeneralLedger!G:G,B6,Raw_GeneralLedger!N:N,A6,Raw_GeneralLedger!O:O,C6) -> 22266.659 | E6: =SUMIFS(Raw_GeneralLedger!M:M,Raw_GeneralLedger!G:G,B6,Raw_GeneralLedger!N:N,A6,Raw_GeneralLedger!O:O,C6) -> 22509.203 | F6: =B6&A6&C6 -> HR20241
A7: 2024 | B7: HR | C7: 2 | D7: =SUMIFS(Raw_GeneralLedger!L:L,Raw_GeneralLedger!G:G,B7,Raw_GeneralLedger!N:N,A7,Raw_GeneralLedger!O:O,C7) -> 17292.03 | E7: =SUMIFS(Raw_GeneralLedger!M:M,Raw_GeneralLedger!G:G,B7,Raw_GeneralLedger!N:N,A7,Raw_GeneralLedger!O:O,C7) -> 26202.711 | F7: =B7&A7&C7 -> HR20242
A8: 2024 | B8: HR | C8: 3 | D8: =SUMIFS(Raw_GeneralLedger!L:L,Raw_GeneralLedger!G:G,B8,Raw_GeneralLedger!N:N,A8,Raw_GeneralLedger!O:O,C8) -> 23462.162 | E8: =SUMIFS(Raw_GeneralLedger!M:M,Raw_GeneralLedger!G:G,B8,Raw_GeneralLedger!N:N,A8,Raw_GeneralLedger!O:O,C8) -> 20818.598 | F8: =B8&A8&C8 -> HR20243
A9: 2024 | B9: HR | C9: 4 | D9: =SUMIFS(Raw_GeneralLedger!L:L,Raw_GeneralLedger!G:G,B9,Raw_GeneralLedger!N:N,A9,Raw_GeneralLedger!O:O,C9) -> 24045.375 | E9: =SUMIFS(Raw_GeneralLedger!M:M,Raw_GeneralLedger!G:G,B9,Raw_GeneralLedger!N:N,A9,Raw_GeneralLedger!O:O,C9) -> 34333.047 | F9: =B9&A9&C9 -> HR20244
A10: 2024 | B10: IT | C10: 1 | D10: =SUMIFS(Raw_GeneralLedger!L:L,Raw_GeneralLedger!G:G,B10,Raw_GeneralLedger!N:N,A10,Raw_GeneralLedger!O:O,C10) -> 19990.602 | E10: =SUMIFS(Raw_GeneralLedger!M:M,Raw_GeneralLedger!G:G,B10,Raw_GeneralLedger!N:N,A10,Raw_GeneralLedger!O:O,C10) -> 29087.134 | F10: =B10&A10&C10 -> IT20241
A11: 2024 | B11: IT | C11: 2 | D11: =SUMIFS(Raw_GeneralLedger!L:L,Raw_GeneralLedger!G:G,B11,Raw_GeneralLedger!N:N,A11,Raw_GeneralLedger!O:O,C11) -> 25527.173 | E11: =SUMIFS(Raw_GeneralLedger!M:M,Raw_GeneralLedger!G:G,B11,Raw_GeneralLedger!N:N,A11,Raw_GeneralLedger!O:O,C11) -> 39689.354 | F11: =B11&A11&C11 -> IT20242
A12: 2024 | B12: IT | C12: 3 | D12: =SUMIFS(Raw_GeneralLedger!L:L,Raw_GeneralLedger!G:G,B12,Raw_GeneralLedger!N:N,A12,Raw_GeneralLedger!O:O,C12) -> 18718.479 | E12: =SUMIFS(Raw_GeneralLedger!M:M,Raw_GeneralLedger!G:G,B12,Raw_GeneralLedger!N:N,A12,Raw_GeneralLedger!O:O,C12) -> 32588.495 | F12: =B12&A12&C12 -> IT20243
A13: 2024 | B13: IT | C13: 4 | D13: =SUMIFS(Raw_GeneralLedger!L:L,Raw_GeneralLedger!G:G,B13,Raw_GeneralLedger!N:N,A13,Raw_GeneralLedger!O:O,C13) -> 19587.604 | E13: =SUMIFS(Raw_GeneralLedger!M:M,Raw_GeneralLedger!G:G,B13,Raw_GeneralLedger!N:N,A13,Raw_GeneralLedger!O:O,C13) -> 33202.278 | F13: =B13&A13&C13 -> IT20244
... A49: 2025 | B49: Operations | C49: 4 | D49: =SUMIFS(Raw_GeneralLedger!L:L,Raw_GeneralLedger!G:G,B49,Raw_GeneralLedger!N:N,A49,Raw_GeneralLedger!O:O,C49) -> 0 | E49: =SUMIFS(Raw_GeneralLedger!M:M,Raw_GeneralLedger!G:G,B49,Raw_GeneralLedger!N:N,A49,Raw_GeneralLedger!O:O,C49) -> 0 | F49: =B49&A49&C49 -> Operations20254

Sheet Variance_Analysis
A1: Fiscal Year | B1: Dept | C1: Quarter | D1: Budget USD | E1: Actual USD | F1: Variance USD | G1: Variance Pct | H1: Key
A2: 2024 | B2: Finance | C2: 1 | D2: =INDEX(Raw_Budget!D:D,MATCH(H2,Raw_Budget!I:I,0)) -> 41215.19 | E2: =INDEX(GL_Summary!D:D,MATCH(H2,GL_Summary!F:F,0)) -> 20434.418 | F2: =IF(E2=0,"N/A",E2-D2) -> -20780.772 | G2: =IF(F2="N/A","N/A",F2/D2) -> -0.50420177 | H2: =B2&A2&C2 -> Finance20241
A3: 2024 | B3: Finance | C3: 2 | D3: =INDEX(Raw_Budget!D:D,MATCH(H3,Raw_Budget!I:I,0)) -> 79918.89 | E3: =INDEX(GL_Summary!D:D,MATCH(H3,GL_Summary!F:F,0)) -> 16330.416 | F3: =IF(E3=0,"N/A",E3-D3) -> -63588.474 | G3: =IF(F3="N/A","N/A",F3/D3) -> -0.79566263 | H3: =B3&A3&C3 -> Finance20242
A4: 2024 | B4: Finance | C4: 3 | D4: =INDEX(Raw_Budget!D:D,MATCH(H4,Raw_Budget!I:I,0)) -> 92014.18 | E4: =INDEX(GL_Summary!D:D,MATCH(H4,GL_Summary!F:F,0)) -> 19545.837 | F4: =IF(E4=0,"N/A",E4-D4) -> -72468.342 | G4: =IF(F4="N/A","N/A",F4/D4) -> -0.78757799 | H4: =B4&A4&C4 -> Finance20243
A5: 2024 | B5: Finance | C5: 4 | D5: =INDEX(Raw_Budget!D:D,MATCH(H5,Raw_Budget!I:I,0)) -> 117680.6 | E5: =INDEX(GL_Summary!D:D,MATCH(H5,GL_Summary!F:F,0)) -> 25935.929 | F5: =IF(E5=0,"N/A",E5-D5) -> -91744.671 | G5: =IF(F5="N/A","N/A",F5/D5) -> -0.77960744 | H5: =B5&A5&C5 -> Finance20244
A6: 2024 | B6: HR | C6: 1 | D6: =INDEX(Raw_Budget!D:D,MATCH(H6,Raw_Budget!I:I,0)) -> 32925.71 | E6: =INDEX(GL_Summary!D:D,MATCH(H6,GL_Summary!F:F,0)) -> 22266.659 | F6: =IF(E6=0,"N/A",E6-D6) -> -10659.051 | G6: =IF(F6="N/A","N/A",F6/D6) -> -0.32373034 | H6: =B6&A6&C6 -> HR20241
A7: 2024 | B7: HR | C7: 2 | D7: =INDEX(Raw_Budget!D:D,MATCH(H7,Raw_Budget!I:I,0)) -> 75074.82 | E7: =INDEX(GL_Summary!D:D,MATCH(H7,GL_Summary!F:F,0)) -> 17292.03 | F7: =IF(E7=0,"N/A",E7-D7) -> -57782.79 | G7: =IF(F7="N/A","N/A",F7/D7) -> -0.76966937 | H7: =B7&A7&C7 -> HR20242
A8: 2024 | B8: HR | C8: 3 | D8: =INDEX(Raw_Budget!D:D,MATCH(H8,Raw_Budget!I:I,0)) -> 42503.06 | E8: =INDEX(GL_Summary!D:D,MATCH(H8,GL_Summary!F:F,0)) -> 23462.162 | F8: =IF(E8=0,"N/A",E8-D8) -> -19040.898 | G8: =IF(F8="N/A","N/A",F8/D8) -> -0.44798889 | H8: =B8&A8&C8 -> HR20243
A9: 2024 | B9: HR | C9: 4 | D9: =INDEX(Raw_Budget!D:D,MATCH(H9,Raw_Budget!I:I,0)) -> 31047.85 | E9: =INDEX(GL_Summary!D:D,MATCH(H9,GL_Summary!F:F,0)) -> 24045.375 | F9: =IF(E9=0,"N/A",E9-D9) -> -7002.4754 | G9: =IF(F9="N/A","N/A",F9/D9) -> -0.22553817 | H9: =B9&A9&C9 -> HR20244
A10: 2024 | B10: IT | C10: 1 | D10: =INDEX(Raw_Budget!D:D,MATCH(H10,Raw_Budget!I:I,0)) -> 26040.63 | E10: =INDEX(GL_Summary!D:D,MATCH(H10,GL_Summary!F:F,0)) -> 19990.602 | F10: =IF(E10=0,"N/A",E10-D10) -> -6050.0282 | G10: =IF(F10="N/A","N/A",F10/D10) -> -0.23233033 | H10: =B10&A10&C10 -> IT20241
A11: 2024 | B11: IT | C11: 2 | D11: =INDEX(Raw_Budget!D:D,MATCH(H11,Raw_Budget!I:I,0)) -> 125902.24 | E11: =INDEX(GL_Summary!D:D,MATCH(H11,GL_Summary!F:F,0)) -> 25527.173 | F11: =IF(E11=0,"N/A",E11-D11) -> -100375.07 | G11: =IF(F11="N/A","N/A",F11/D11) -> -0.79724608 | H11: =B11&A11&C11 -> IT20242
A12: 2024 | B12: IT | C12: 3 | D12: =INDEX(Raw_Budget!D:D,MATCH(H12,Raw_Budget!I:I,0)) -> 100055.73 | E12: =INDEX(GL_Summary!D:D,MATCH(H12,GL_Summary!F:F,0)) -> 18718.479 | F12: =IF(E12=0,"N/A",E12-D12) -> -81337.251 | G12: =IF(F12="N/A","N/A",F12/D12) -> -0.81291947 | H12: =B12&A12&C12 -> IT20243
A13: 2024 | B13: IT | C13: 4 | D13: =INDEX(Raw_Budget!D:D,MATCH(H13,Raw_Budget!I:I,0)) -> 72786.96 | E13: =INDEX(GL_Summary!D:D,MATCH(H13,GL_Summary!F:F,0)) -> 19587.604 | F13: =IF(E13=0,"N/A",E13-D13) -> -53199.356 | G13: =IF(F13="N/A","N/A",F13/D13) -> -0.7308913 | H13: =B13&A13&C13 -> IT20244
... A49: 2025 | B49: Operations | C49: 4 | D49: =INDEX(Raw_Budget!D:D,MATCH(H49,Raw_Budget!I:I,0)) -> 28580.31 | E49: =INDEX(GL_Summary!D:D,MATCH(H49,GL_Summary!F:F,0)) -> 0 | F49: =IF(E49=0,"N/A",E49-D49) -> N/A | G49: =IF(F49="N/A","N/A",F49/D49) -> N/A | H49: =B49&A49&C49 -> Operations20254

Sheet Pivot by Dept 
A3: Row Labels | B3: Sum of Budget USD | C3: Sum of Actual USD | D3: Sum of Variance USD
A4: Finance | B4: 642803.78 | C4: 134610.37 | D4: -328414.93
A5: HR | B5: 528395.83 | C5: 120959.52 | D5: -196707.08
A6: IT | B6: 560662.26 | C6: 123295.98 | D6: -366689.96
A7: Marketing | B7: 812792.96 | C7: 128831.64 | D7: -478795.2
A8: Operations | B8: 479846.31 | C8: 97392.138 | D8: -316341.09
A9: Sales | B9: 712383.88 | C9: 116852 | D9: -368703.01
A10: Grand Total | B10: 3736885 | C10: 721941.64 | D10: -2055651.3

Sheet Pivot Trend
A3: Row Labels | B3: Sum of Budget USD | C3: Sum of Actual USD
A4: 2024 | B4: 1895459.6 | C4: 473537.68
A5: 1 | B5: 338497.17 | C5: 109562.54
A6: 2 | B6: 560141.43 | C6: 120315.6
A7: 3 | B7: 479210.89 | C7: 124011.09
A8: 4 | B8: 517610.13 | C8: 119648.44
A9: 2025 | B9: 1841425.4 | C9: 248403.96
A10: 1 | B10: 498016.19 | C10: 130913.62
A11: 2 | B11: 384117.11 | C11: 117490.34
A12: 3 | B12: 458902.88 | C12: 0
A13: 4 | B13: 500389.22 | C13: 0
A14: Grand Total | B14: 3736885 | C14: 721941.64

Sheet Pivot Ranking
A2: Row Labels | B2: Sum of Variance USD
A3: Operations20244 | B3: -129846.27
A4: Marketing20243 | B4: -117922.49
A5: IT20242 | B5: -100375.07
A6: Marketing20252 | B6: -100140.03
A7: IT20251 | B7: -97659.008
A8: Finance20244 | B8: -91744.671
A9: Sales20242 | B9: -91605.535
A10: Marketing20242 | B10: -90034.008
A11: Marketing20244 | B11: -86474.733
A12: Operations20241 | B12: -86125.21
A13: Grand Total | B13: -991927.03

Sheet Pivot ExpensebyCat
A3: Row Labels | B3: Sum of Amount USD
A4: Training | B4: 72347.806
A5: Travel | B5: 74634.967
A6: Grand Total | B6: 146982.77
